<?xml version="1.0" encoding="utf-8"?>
<!-- =================================================================================== -->
<!-- |    This document was autogenerated by xacro from cara.xacro                     | -->
<!-- |    EDITING THIS FILE BY HAND IS NOT RECOMMENDED                                 | -->
<!-- =================================================================================== -->
<robot name="cara">
  <material name="black">
    <color rgba="0.0 0.0 0.0 1.0"/>
  </material>
  <material name="green">
    <color rgba="0.0 0.8 0.0 1.0"/>
  </material>
  <material name="grey">
    <color rgba="0.2 0.2 0.2 1.0"/>
  </material>
  <material name="transparent_acrylic">
    <color rgba="0.8 0.8 0.8 0.4"/>
  </material>
  <material name="transparent_acrylic_dark">
    <color rgba="0.4 0.4 0.4 0.4"/>
  </material>
  <material name="aluminium">
    <color rgba="0.8 0.8 0.8 1"/>
  </material>
  <material name="aluminium_dark">
    <color rgba="0.6 0.6 0.6 1"/>
  </material>
  <material name="plastic">
    <color rgba="0.95 0.95 0.95 1"/>
  </material>
  <material name="black_plastic">
    <color rgba="0.0 0.0 0.0 1"/>
  </material>
  <material name="blue">
    <color rgba="0 0 1.0 1"/>
  </material>
  <material name="bronze">
    <color rgba="0.8039 0.498 0.196 1"/>
  </material>
  <material name="orange">
    <color rgba="1.0 0.423529411765 0.0392156862745 1.0"/>
  </material>
  <material name="brown">
    <color rgba="0.870588235294 0.811764705882 0.764705882353 1.0"/>
  </material>
  <material name="red">
    <color rgba="0.8 0.0 0.0 1.0"/>
  </material>
  <material name="white">
    <color rgba="1.0 1.0 1.0 1.0"/>
  </material>
  <gazebo>
    <plugin filename="libgazebo_ros_planar_move.so" name="object_controller">
      <commandTopic>cmd_vel</commandTopic>
      <odometryTopic>odom</odometryTopic>
      <odometryFrame>odom</odometryFrame>
      <odometryRate>30.0</odometryRate>
      <robotBaseFrame>base_link</robotBaseFrame>
    </plugin>
  </gazebo>
  <!-- ======================================================= Base Link ====================================================================== -->
  <link name="base_link">
    <visual>
      <origin rpy="1.57079632679 0 0" xyz="0.01 0 0"/>
      <geometry>
        <mesh filename="package://cara/models/base.stl" scale="0.001 0.001 0.001"/>
      </geometry>
      <material name="transparent_acrylic"/>
    </visual>
    <inertial>
      <mass value="8"/>
      <inertia ixx="0.000231" ixy="0.0" ixz="0.0" iyy="0.000439" iyz="-0.000001" izz="0.999454"/>
    </inertial>
    <collision>
      <origin rpy="0 0 0.785398163397" xyz="0 0 0.05"/>
      <geometry>
        <box size="0.52 0.52 0.11"/>
      </geometry>
    </collision>
    <collision>
      <origin rpy="0 0 0" xyz="0 0 0.07"/>
      <geometry>
        <cylinder length="0.205" radius=".07"/>
      </geometry>
    </collision>
  </link>
  <!-- =======================================================Wheel 1====================================================================== -->
  <link name="c_clamp_1">
    <visual>
      <origin rpy="1.57079632679 0 0" xyz="-0.31 0.05 0.09"/>
      <geometry>
        <mesh filename="package://cara/models/c_clamp.stl" scale="0.001 0.001 0.001"/>
      </geometry>
      <material name="aluminium"/>
    </visual>
  </link>
  <joint name="base_c_clamp_1" type="fixed">
    <parent link="base_link"/>
    <child link="c_clamp_1"/>
  </joint>
  <link name="motor_1">
    <visual>
      <origin rpy="1.57079632679 0 1.57079632679" xyz="-0.298 0 0.045"/>
      <geometry>
        <mesh filename="package://cara/models/motor.stl" scale="0.001 0.001 0.001"/>
      </geometry>
      <material name="aluminium_dark"/>
    </visual>
  </link>
  <joint name="c_clamp_motor_1" type="fixed">
    <parent link="c_clamp_1"/>
    <child link="motor_1"/>
  </joint>
  <link name="shaft_1">
    <visual>
      <origin rpy="0 0 0" xyz="0 0 0"/>
      <geometry>
        <mesh filename="package://cara/models/motor_shaft.stl" scale="0.001 0.001 0.001"/>
      </geometry>
      <material name="plastic"/>
    </visual>
  </link>
  <joint name="motor_shaft_1" type="continuous">
    <parent link="base_link"/>
    <child link="shaft_1"/>
    <axis xyz="1 0 0"/>
    <origin rpy="0 0 3.14159265359" xyz="-0.32 0 0.045"/>
  </joint>
  <link name="wheel_1">
    <visual>
      <origin rpy="0 0 1.57079632679" xyz="0.02 0 0"/>
      <geometry>
        <mesh filename="package://cara/models/wheel2.dae"/>
      </geometry>
    </visual>
    <inertial>
      <mass value="0.5"/>
      <inertia ixx="0.0" ixy="0.0" ixz="0.0" iyy="0.000001" iyz="0.0" izz="0.0"/>
    </inertial>
    <collision>
      <origin rpy="0 1.57079632679 0" xyz="0.027 0 0.0"/>
      <geometry>
        <cylinder length="0.045" radius="0.08"/>
      </geometry>
    </collision>
  </link>
  <joint name="shaft_wheel_1" type="fixed">
    <parent link="shaft_1"/>
    <child link="wheel_1"/>
  </joint>
  <!-- =======================================================Wheel 2====================================================================== -->
  <link name="c_clamp_2">
    <visual>
      <origin rpy="1.57079632679 0 -1.57079632679" xyz="0.05 0.31 0.09"/>
      <geometry>
        <mesh filename="package://cara/models/c_clamp.stl" scale="0.001 0.001 0.001"/>
      </geometry>
      <material name="aluminium"/>
    </visual>
  </link>
  <joint name="base_c_clamp_2" type="fixed">
    <parent link="base_link"/>
    <child link="c_clamp_2"/>
  </joint>
  <link name="motor_2">
    <visual>
      <origin rpy="1.57079632679 -3.14159265359 0" xyz="0 0.298 0.045"/>
      <geometry>
        <mesh filename="package://cara/models/motor.stl" scale="0.001 0.001 0.001"/>
      </geometry>
      <material name="aluminium_dark"/>
    </visual>
  </link>
  <joint name="c_clamp_motor_2" type="fixed">
    <parent link="c_clamp_2"/>
    <child link="motor_2"/>
  </joint>
  <link name="shaft_2">
    <visual>
      <origin rpy="0 0 0" xyz="0 0 0"/>
      <geometry>
        <mesh filename="package://cara/models/motor_shaft.stl" scale="0.001 0.001 0.001"/>
      </geometry>
      <material name="plastic"/>
    </visual>
  </link>
  <joint name="motor_shaft_2" type="continuous">
    <parent link="base_link"/>
    <child link="shaft_2"/>
    <origin rpy="0 0 1.57079632679" xyz="0 0.32 0.045"/>
  </joint>
  <link name="wheel_2">
    <visual>
      <origin rpy="0 0 1.57079632679" xyz="0.02 0 0"/>
      <geometry>
        <mesh filename="package://cara/models/wheel2.dae"/>
      </geometry>
    </visual>
    <inertial>
      <mass value="0.5"/>
      <inertia ixx="0.0" ixy="0.0" ixz="0.0" iyy="0.000001" iyz="0.0" izz="0.0"/>
    </inertial>
    <collision>
      <origin rpy="0 1.57079632679 0" xyz="0.027 0 0.0"/>
      <geometry>
        <cylinder length="0.045" radius="0.08"/>
      </geometry>
    </collision>
  </link>
  <joint name="shaft_wheel_2" type="fixed">
    <parent link="shaft_2"/>
    <child link="wheel_2"/>
  </joint>
  <!-- =======================================================Wheel 3====================================================================== -->
  <link name="c_clamp_3">
    <visual>
      <origin rpy="1.57079632679 0 3.14159265359" xyz="0.31 -0.05 0.09"/>
      <geometry>
        <mesh filename="package://cara/models/c_clamp.stl" scale="0.001 0.001 0.001"/>
      </geometry>
      <material name="aluminium"/>
    </visual>
  </link>
  <joint name="base_c_clamp_3" type="fixed">
    <parent link="base_link"/>
    <child link="c_clamp_3"/>
  </joint>
  <link name="motor_3">
    <visual>
      <origin rpy="1.57079632679 0 -1.57079632679" xyz="0.298 0 0.045"/>
      <geometry>
        <mesh filename="package://cara/models/motor.stl" scale="0.001 0.001 0.001"/>
      </geometry>
      <material name="aluminium_dark"/>
    </visual>
  </link>
  <joint name="c_clamp_motor_3" type="fixed">
    <parent link="c_clamp_3"/>
    <child link="motor_3"/>
  </joint>
  <link name="shaft_3">
    <visual>
      <origin rpy="0 0 0" xyz="0 0 0"/>
      <geometry>
        <mesh filename="package://cara/models/motor_shaft.stl" scale="0.001 0.001 0.001"/>
      </geometry>
      <material name="plastic"/>
    </visual>
  </link>
  <joint name="motor_shaft_3" type="continuous">
    <parent link="base_link"/>
    <child link="shaft_3"/>
    <origin rpy="0 0 0" xyz="0.32 0 0.045"/>
  </joint>
  <link name="wheel_3">
    <visual>
      <origin rpy="0 0 1.57079632679" xyz="0.02 0 0"/>
      <geometry>
        <mesh filename="package://cara/models/wheel2.dae"/>
      </geometry>
    </visual>
    <inertial>
      <mass value="0.5"/>
      <inertia ixx="0.0" ixy="0.0" ixz="0.0" iyy="0.000001" iyz="0.0" izz="0.0"/>
    </inertial>
    <collision>
      <origin rpy="0 1.57079632679 0" xyz="0.027 0 0.0"/>
      <geometry>
        <cylinder length="0.045" radius="0.08"/>
      </geometry>
    </collision>
  </link>
  <joint name="shaft_wheel_3" type="fixed">
    <parent link="shaft_3"/>
    <child link="wheel_3"/>
  </joint>
  <!-- =======================================================Wheel 4====================================================================== -->
  <link name="c_clamp_4">
    <visual>
      <origin rpy="1.57079632679 0 1.57079632679" xyz="-0.05 -0.31 0.09"/>
      <geometry>
        <mesh filename="package://cara/models/c_clamp.stl" scale="0.001 0.001 0.001"/>
      </geometry>
      <material name="aluminium"/>
    </visual>
  </link>
  <joint name="base_c_clamp_4" type="fixed">
    <parent link="base_link"/>
    <child link="c_clamp_4"/>
  </joint>
  <link name="motor_4">
    <visual>
      <origin rpy="1.57079632679 0 3.14159265359" xyz="0 -0.298 0.045"/>
      <geometry>
        <mesh filename="package://cara/models/motor.stl" scale="0.001 0.001 0.001"/>
      </geometry>
      <material name="aluminium_dark"/>
    </visual>
  </link>
  <joint name="c_clamp_motor_4" type="fixed">
    <parent link="c_clamp_4"/>
    <child link="motor_4"/>
  </joint>
  <link name="shaft_4">
    <visual>
      <origin rpy="0 0 0" xyz="0 0 0"/>
      <geometry>
        <mesh filename="package://cara/models/motor_shaft.stl" scale="0.001 0.001 0.001"/>
      </geometry>
      <material name="plastic"/>
    </visual>
  </link>
  <joint name="motor_shaft_4" type="continuous">
    <parent link="base_link"/>
    <child link="shaft_4"/>
    <origin rpy="0 0 -1.57079632679" xyz="0 -0.32 0.045"/>
  </joint>
  <link name="wheel_4">
    <visual>
      <origin rpy="0 0 1.57079632679" xyz="0.02 0 0"/>
      <geometry>
        <mesh filename="package://cara/models/wheel2.dae"/>
      </geometry>
    </visual>
    <inertial>
      <mass value="0.5"/>
      <inertia ixx="0.0" ixy="0.0" ixz="0.0" iyy="0.000001" iyz="0.0" izz="0.0"/>
    </inertial>
    <collision>
      <origin rpy="0 1.57079632679 0" xyz="0.027 0 0.0"/>
      <geometry>
        <cylinder length="0.045" radius="0.08"/>
      </geometry>
    </collision>
  </link>
  <joint name="shaft_wheel_4" type="fixed">
    <parent link="shaft_4"/>
    <child link="wheel_4"/>
  </joint>
  <!-- ======================================================= Top Plate ====================================================================== -->
  <link name="top_plate">
    <visual>
      <origin rpy="1.57079632679 0 0" xyz="0.01 0 0.0836"/>
      <geometry>
        <mesh filename="package://cara/models/top_plate.stl" scale="0.001 0.001 0.001"/>
      </geometry>
      <material name="blue"/>
    </visual>
  </link>
  <joint name="base_link_top_plate" type="fixed">
    <parent link="base_link"/>
    <child link="top_plate"/>
  </joint>
  <!-- ======================================================= Circuit Plate ====================================================================== -->
  <link name="circuit_plate">
    <visual>
      <origin rpy="1.57079632679 0 -3.92699081699" xyz="0 0 0.093"/>
      <geometry>
        <mesh filename="package://cara/models/circuit_plate.stl" scale="0.001 0.001 0.001"/>
      </geometry>
      <material name="plastic"/>
    </visual>
  </link>
  <joint name="base_link_circuit_plate" type="fixed">
    <parent link="top_plate"/>
    <child link="circuit_plate"/>
  </joint>
  <!-- ======================================================= feedback ====================================================================== -->
  <link name="feedback">
    <visual>
      <origin rpy="1.57079632679 0 0.785398163397" xyz="0.063 0.1 -0.06"/>
      <geometry>
        <mesh filename="package://cara/models/feedback.stl" scale="0.001 0.001 0.001"/>
      </geometry>
      <material name="aluminium_dark"/>
    </visual>
  </link>
  <joint name="base_link_feedback" type="fixed">
    <parent link="base_link"/>
    <child link="feedback"/>
  </joint>
  <link name="s1">
    <visual>
      <origin rpy="1.57079632679 0 0" xyz="0.073 0.06 0.006"/>
      <geometry>
        <mesh filename="package://cara/models/stud.stl" scale="0.001 0.001 0.001"/>
      </geometry>
      <material name="bronze"/>
    </visual>
  </link>
  <joint name="feedback_s1" type="fixed">
    <parent link="feedback"/>
    <child link="s1"/>
  </joint>
  <link name="s2">
    <visual>
      <origin rpy="1.57079632679 0 0" xyz="-0.073 0.06 0.006"/>
      <geometry>
        <mesh filename="package://cara/models/stud.stl" scale="0.001 0.001 0.001"/>
      </geometry>
      <material name="bronze"/>
    </visual>
  </link>
  <joint name="feedback_s2" type="fixed">
    <parent link="feedback"/>
    <child link="s2"/>
  </joint>
  <link name="s3">
    <visual>
      <origin rpy="1.57079632679 0 0" xyz="0.073 -0.06 0.006"/>
      <geometry>
        <mesh filename="package://cara/models/stud.stl" scale="0.001 0.001 0.001"/>
      </geometry>
      <material name="bronze"/>
    </visual>
  </link>
  <joint name="feedback_s3" type="fixed">
    <parent link="feedback"/>
    <child link="s3"/>
  </joint>
  <link name="s4">
    <visual>
      <origin rpy="1.57079632679 0 0" xyz="-0.073 -0.06 0.006"/>
      <geometry>
        <mesh filename="package://cara/models/stud.stl" scale="0.001 0.001 0.001"/>
      </geometry>
      <material name="bronze"/>
    </visual>
  </link>
  <joint name="feedback_s4" type="fixed">
    <parent link="feedback"/>
    <child link="s4"/>
  </joint>
  <link name="s5">
    <visual>
      <origin rpy="1.57079632679 0 0" xyz="0.06 0.0735 0.006"/>
      <geometry>
        <mesh filename="package://cara/models/stud.stl" scale="0.001 0.001 0.001"/>
      </geometry>
      <material name="bronze"/>
    </visual>
  </link>
  <joint name="feedback_s5" type="fixed">
    <parent link="feedback"/>
    <child link="s5"/>
  </joint>
  <link name="s6">
    <visual>
      <origin rpy="1.57079632679 0 0" xyz="-0.06 0.0735 0.006"/>
      <geometry>
        <mesh filename="package://cara/models/stud.stl" scale="0.001 0.001 0.001"/>
      </geometry>
      <material name="bronze"/>
    </visual>
  </link>
  <joint name="feedback_s6" type="fixed">
    <parent link="feedback"/>
    <child link="s6"/>
  </joint>
  <link name="s7">
    <visual>
      <origin rpy="1.57079632679 0 0" xyz="0.06 -0.0735 0.006"/>
      <geometry>
        <mesh filename="package://cara/models/stud.stl" scale="0.001 0.001 0.001"/>
      </geometry>
      <material name="bronze"/>
    </visual>
  </link>
  <joint name="feedback_s7" type="fixed">
    <parent link="feedback"/>
    <child link="s7"/>
  </joint>
  <link name="s8">
    <visual>
      <origin rpy="1.57079632679 0 0" xyz="-0.06 -0.0735 0.006"/>
      <geometry>
        <mesh filename="package://cara/models/stud.stl" scale="0.001 0.001 0.001"/>
      </geometry>
      <material name="bronze"/>
    </visual>
  </link>
  <joint name="feedback_s8" type="fixed">
    <parent link="feedback"/>
    <child link="s8"/>
  </joint>
  <!-- ======================================================= lidar Base ====================================================================== -->
  <link name="lidar_base">
    <visual>
      <origin rpy="1.57079632679 0 0" xyz="0.01 0 0.1134"/>
      <geometry>
        <mesh filename="package://cara/models/lidar_base.stl" scale="0.001 0.001 0.001"/>
      </geometry>
      <material name="transparent_acrylic_dark"/>
    </visual>
  </link>
  <joint name="circuit_plate_lidar_base" type="fixed">
    <parent link="circuit_plate"/>
    <child link="lidar_base"/>
  </joint>
  <link name="s9">
    <visual>
      <origin rpy="1.57079632679 0 0" xyz="-0.021 0.0321 0.098"/>
      <geometry>
        <mesh filename="package://cara/models/stud.stl" scale="0.001 0.001 0.001"/>
      </geometry>
      <material name="bronze"/>
    </visual>
  </link>
  <joint name="lidar_base_s9" type="fixed">
    <parent link="lidar_base"/>
    <child link="s9"/>
  </joint>
  <link name="s10">
    <visual>
      <origin rpy="1.57079632679 0 0" xyz="0.041 0.0321 0.098"/>
      <geometry>
        <mesh filename="package://cara/models/stud.stl" scale="0.001 0.001 0.001"/>
      </geometry>
      <material name="bronze"/>
    </visual>
  </link>
  <joint name="lidar_base_s10" type="fixed">
    <parent link="lidar_base"/>
    <child link="s10"/>
  </joint>
  <link name="s11">
    <visual>
      <origin rpy="1.57079632679 0 0" xyz="0.041 -0.0321 0.098"/>
      <geometry>
        <mesh filename="package://cara/models/stud.stl" scale="0.001 0.001 0.001"/>
      </geometry>
      <material name="bronze"/>
    </visual>
  </link>
  <joint name="lidar_base_s11" type="fixed">
    <parent link="lidar_base"/>
    <child link="s11"/>
  </joint>
  <link name="s12">
    <visual>
      <origin rpy="1.57079632679 0 0" xyz="-0.021 -0.0321 0.098"/>
      <geometry>
        <mesh filename="package://cara/models/stud.stl" scale="0.001 0.001 0.001"/>
      </geometry>
      <material name="bronze"/>
    </visual>
  </link>
  <joint name="lidar_base_s12" type="fixed">
    <parent link="lidar_base"/>
    <child link="s12"/>
  </joint>
  <!-- ======================================================= RPlidar ====================================================================== -->
  <link name="lidar_bottom">
    <visual>
      <origin rpy="1.57079632679 0 0" xyz="0.0 0 0.161"/>
      <geometry>
        <mesh filename="package://cara/models/lidar_bottom.stl" scale="0.001 0.001 0.001"/>
      </geometry>
      <material name="aluminium"/>
    </visual>
  </link>
  <joint name="lidar_base_lidar_bottom" type="fixed">
    <parent link="lidar_base"/>
    <child link="lidar_bottom"/>
  </joint>
  <link name="lidar_up">
    <visual>
      <origin rpy="1.57079632679 0 0" xyz="0.0 0 0.158"/>
      <geometry>
        <mesh filename="package://cara/models/lidar_up.stl" scale="0.001 0.001 0.001"/>
      </geometry>
      <material name="black_plastic"/>
    </visual>
  </link>
  <joint name="lidar_bottom_lidar_up" type="fixed">
    <parent link="lidar_bottom"/>
    <child link="lidar_up"/>
  </joint>
  <link name="rplidar_frame">
    <visual>
      <geometry>
        <sphere radius="0.001"/>
      </geometry>
      <material name="blue"/>
    </visual>
  </link>
  <joint name="base_link_rplidar_frame" type="fixed">
    <origin rpy="0 0 0" xyz="0.0 0 0.16"/>
    <parent link="base_link"/>
    <child link="rplidar_frame"/>
  </joint>
  <gazebo reference="rplidar_frame">
    <sensor name="rplidar_sensor" type="ray">
      <pose>0 0 0 0 0 0</pose>
      <visualize>true</visualize>
      <update_rate>8</update_rate>
      <ray>
        <scan>
          <horizontal>
            <samples>360</samples>
            <resolution>1</resolution>
            <min_angle>0</min_angle>
            <max_angle>6.28318530718</max_angle>
          </horizontal>
        </scan>
        <range>
          <min>0.2</min>
          <max>6.0</max>
          <resolution>0.5</resolution>
        </range>
        <noise>
          <type>gaussian</type>
          <!-- Noise parameters based on published spec for Hokuyo laser
               achieving "+-30mm" accuracy at range < 10m.  A mean of 0.0m and
               stddev of 0.01m will put 99.7% of samples within 0.03m of the true
               reading. -->
          <mean>0.0</mean>
          <stddev>0.01</stddev>
        </noise>
      </ray>
      <plugin filename="libgazebo_ros_laser.so" name="gazebo_ros_rplidar_controller">
        <topicName>/cara/scan</topicName>
        <frameName>/rplidar_frame</frameName>
      </plugin>
    </sensor>
  </gazebo>
  <link name="x">
    <visual>
      <origin rpy="0 0 0" xyz="1.0 0 0"/>
      <geometry>
        <sphere radius="0.1"/>
      </geometry>
      <material name="blue"/>
    </visual>
  </link>
  <joint name="base_link_x" type="fixed">
    <parent link="base_link"/>
    <child link="x"/>
  </joint>
  <link name="y">
    <visual>
      <origin rpy="0 0 0" xyz="0 1 0"/>
      <geometry>
        <sphere radius="0.1"/>
      </geometry>
      <material name="bronze"/>
    </visual>
  </link>
  <joint name="base_link_y" type="fixed">
    <parent link="base_link"/>
    <child link="y"/>
  </joint>
  <link name="imu">
    <visual>
      <origin rpy="0 0 0" xyz="0.16 0.05 0.02"/>
      <geometry>
        <box size="0.05 0.03 0.004"/>
      </geometry>
      <material name="blue"/>
    </visual>
  </link>
  <joint name="base_link_imu" type="fixed">
    <parent link="base_link"/>
    <child link="imu"/>
  </joint>
</robot>

