<?xml version="1.0" encoding="utf-8"?>
<robot name="cara">
 <material name="black">
    <color rgba="0.0 0.0 0.0 1.0"/>
  </material>
   <material name="light_black">
    <color rgba="0.0 0.0 0.0 0.9"/>
  </material>
  <material name="green">
    <color rgba="0.0 0.8 0.0 1.0"/>
  </material>
  <material name="grey">
    <color rgba="0.2 0.2 0.2 1.0"/>
  </material>
  <material name="transparent_acrylic">
    <color rgba="0.8 0.8 0.8 0.4"/>
  </material>
  <material name="transparent_acrylic_dark">
    <color rgba="0.4 0.4 0.4 0.4"/>
  </material>
  <material name="aluminium">
    <color rgba="0.8 0.8 0.8 1"/>
  </material>
  <material name="aluminium_dark">
    <color rgba="0.6 0.6 0.6 1"/>
  </material>
  <material name="plastic">
    <color rgba="0.95 0.95 0.95 1"/>
  </material>
  <material name="black_plastic">
    <color rgba="0.0 0.0 0.0 1"/>
  </material>
  <material name="blue">
    <color rgba="0 0 1.0 1"/>
  </material>
  <material name="bronze">
    <color rgba="0.8039 0.498 0.196 1"/>
  </material>
  <material name="orange">
    <color rgba="1.0 0.423529411765 0.0392156862745 1.0"/>
  </material>
  <material name="brown">
    <color rgba="0.870588235294 0.811764705882 0.764705882353 1.0"/>
  </material>
  <material name="red">
    <color rgba="0.8 0.0 0.0 1.0"/>
  </material>
  <material name="white">
    <color rgba="1.0 1.0 1.0 1.0"/>
  </material>
  <gazebo>
  <plugin name="gazebo_ros_control" filename="libgazebo_ros_control.so">
      <robotNamespace>/</robotNamespace>
      </plugin>
    <plugin filename="libgazebo_ros_planar_move.so" name="object_controller">
      <commandTopic>cmd_vel</commandTopic>
      <odometryTopic>odom</odometryTopic>
      <odometryFrame>odom</odometryFrame>
      <odometryRate>30.0</odometryRate>
      <robotBaseFrame>base_link</robotBaseFrame>
    </plugin>
  </gazebo>
  <!-- ======================================================= Base Link ====================================================================== -->
  <link name="base_link">
    <visual>
      <origin rpy="1.57080 0 0" xyz="-0.16 -0.035 0.082"/>
      <geometry>
        <mesh filename="package://cara_description/meshes/chassis.stl" scale="0.001 0.001 0.001"/>
      </geometry>
      <material name="aluminium">
        <color rgba="0.8 0.8 0.8 1"/>
       </material>
    </visual>

    <collision>
      <origin rpy="0 0 0" xyz="0 0 0.2"/>
      <geometry>
        <box size="0.6 0.6 0.4048"/>
      </geometry>
    </collision>
    <collision>
      <origin rpy="0 0 0" xyz="0 0 0.41"/>
      <geometry>
        <cylinder length="0.205" radius=".07"/>
      </geometry>
    </collision>
  </link>
  <!-- =======================================================Motor & Wheel L====================================================================== -->
  <link name="motorL">
    <visual>
      <origin rpy="0 0 0" xyz="0.08 0.16 0.035"/>
      <geometry>
        <mesh filename="package://cara_description/meshes/motor-and-mount.stl" scale=".025 .025 .025"/>
      </geometry>
      <material name="aluminium"/>
    </visual>
    <inertial>
        <origin rpy="0 0 0" xyz="0.08 0.16 0.035"/>
        <mass value="1" />
        <inertia
          ixx="1.0" ixy="0.0" ixz="0.0"
          iyy="1.0" iyz="0.0"
          izz="1.0" />
    </inertial>
  </link>
  <joint name="base_and_motorL" type="fixed">
    <parent link="base_link"/>
    <child link= "motorL"/>
  </joint>

  <link name="wheelL">
    <visual>
      <origin rpy="0 0 1.57079632679" xyz="0.02 0.255 0.055"/>
      <geometry>
        <mesh filename="package://cara_description/meshes/wheel.stl" scale=".001 .001 .001"/>
      </geometry>
      <material name="light_black"/>
    </visual>
  </link>
  <joint name="motor_and_wheelL" type="continuous">
    <parent link="motorL"/>
    <child link= "wheelL"/>
	<axis xyz="0 1 0"/>
  </joint>

  <transmission name="motor_L_trans">
    <type>transmission_interface/SimpleTransmission</type>
    <joint name="motor_and_wheelL">
      <hardwareInterface>hardware_interface/EffortJointInterface</hardwareInterface>
    </joint>
    <actuator name="motorL">
      <hardwareInterface>hardware_interface/EffortJointInterface</hardwareInterface>
      <mechanicalReduction>19</mechanicalReduction>
    </actuator>
  </transmission>


 <!-- =======================================================Wheel R====================================================================== -->
  <link name="motorR">
    <visual>
      <origin rpy="0 0 -3.14079632679" xyz="-0.055 -0.155 0.035"/>
      <geometry>
        <mesh filename="package://cara_description/meshes/motor-and-mount.stl" scale=".025 .025 .025"/>
      </geometry>
      <material name="aluminium"/>
    </visual>
     <inertial>
        <origin rpy="0 0 0" xyz="0.08 0.16 0.035"/>
        <mass value="1" />
        <inertia
          ixx="1.0" ixy="0.0" ixz="0.0"
          iyy="1.0" iyz="0.0"
          izz="1.0" />
        </inertial>
  </link>
 <joint name="base_and_motorR" type="fixed">
    <parent link="base_link"/>
    <child link= "motorR"/>

 </joint>

<link name="wheelR">
    <visual>
      <origin rpy="0 0 1.57079632679" xyz="0.02 -0.21 0.055"/>
      <geometry>
        <mesh filename="package://cara_description/meshes/wheel.stl" scale=".001 .001 .001"/>
      </geometry>
      <material name="light_black"/>
    </visual>
  </link>
  <joint name="motor_and_wheelR" type="continuous">
    <parent link="motorR"/>
    <child link= "wheelR"/>
	<axis xyz="0 1 0"/>
  </joint>

  <transmission name="motor_R_trans">
    <type>transmission_interface/SimpleTransmission</type>
    <joint name="motor_and_wheelR">
      <hardwareInterface>hardware_interface/EffortJointInterface</hardwareInterface>
    </joint>
    <actuator name="motorR">
      <hardwareInterface>hardware_interface/EffortJointInterface</hardwareInterface>
      <mechanicalReduction>19</mechanicalReduction>
    </actuator>
  </transmission>

  <!-- ======================================================= Frame ====================================================================== -->
  <link name="frame">
    <visual>
      <origin rpy="1.57079632679 0 1.57079632679" xyz="-0.08 -0.03 0.06"/>
      <geometry>
        <mesh filename="package://cara_description/meshes/frame.stl" scale="0.001 0.001 0.001"/>
      </geometry>
      <material name="transparent_acrylic_dark"/>
    </visual>
  </link>
  <joint name="base_link_frame" type="fixed">
    <parent link="base_link"/>
    <child link="frame"/>
  </joint>

  <!-- ======================================================= lidar Base ====================================================================== -->
  <link name="lidar_base">
    <visual>
      <origin rpy="1.57079632679 0 3.14159" xyz="-0.1146 0 0.2634"/>
      <geometry>
        <mesh filename="package://cara_description/meshes/lidar_base.stl" scale="0.001 0.001 0.001"/>
      </geometry>
      <material name="transparent_acrylic_dark"/>
    </visual>
  </link>
  <joint name="frame_lidar_base" type="fixed">
    <parent link="frame"/>
    <child link="lidar_base"/>
  </joint>
  <link name="s9">
    <visual>
      <origin rpy="1.57079632679 0 3.14159" xyz="-0.1456 0.0321 0.248"/>
      <geometry>
        <mesh filename="package://cara_description/meshes/stud.stl" scale="0.001 0.001 0.001"/>
      </geometry>
      <material name="bronze"/>
    </visual>
  </link>
  <joint name="lidar_base_s9" type="fixed">
    <parent link="lidar_base"/>
    <child link="s9"/>
  </joint>
  <link name="s10">
    <visual>
      <origin rpy="1.57079632679 0 3.14159" xyz="-0.0836 0.0321 0.248"/>
      <geometry>
        <mesh filename="package://cara_description/meshes/stud.stl" scale="0.001 0.001 0.001"/>
      </geometry>
      <material name="bronze"/>
    </visual>
  </link>
  <joint name="lidar_base_s10" type="fixed">
    <parent link="lidar_base"/>
    <child link="s10"/>
  </joint>
  <link name="s11">
    <visual>
      <origin rpy="1.57079632679 0 3.14159" xyz="-0.0836 -0.0321 0.248"/>
      <geometry>
        <mesh filename="package://cara_description/meshes/stud.stl" scale="0.001 0.001 0.001"/>
      </geometry>
      <material name="bronze"/>
    </visual>
  </link>
  <joint name="lidar_base_s11" type="fixed">
    <parent link="lidar_base"/>
    <child link="s11"/>
  </joint>
  <link name="s12">
    <visual>
      <origin rpy="1.57079632679 0 3.14159" xyz="-0.1456 -0.0321 0.248"/>
      <geometry>
        <mesh filename="package://cara_description/meshes/stud.stl" scale="0.001 0.001 0.001"/>
      </geometry>
      <material name="bronze"/>
    </visual>
  </link>
  <joint name="lidar_base_s12" type="fixed">
    <parent link="lidar_base"/>
    <child link="s12"/>
  </joint>
  <!-- ======================================================= RPlidar ====================================================================== -->
  <link name="lidar_bottom">
    <visual>
      <origin rpy="1.57079632679 0 3.14159" xyz="-0.1246 0 0.281"/>
      <geometry>
        <mesh filename="package://cara_description/meshes/lidar_bottom.stl" scale="0.001 0.001 0.001"/>
      </geometry>
      <material name="aluminium"/>
    </visual>
  </link>
  <joint name="lidar_base_lidar_bottom" type="fixed">
    <parent link="lidar_base"/>
    <child link="lidar_bottom"/>
  </joint>
  <link name="lidar_up">
    <visual>
      <origin rpy="1.57079632679 0 3.14159" xyz="-0.1246 0 0.278"/>
      <geometry>
        <mesh filename="package://cara_description/meshes/lidar_up.stl" scale="0.001 0.001 0.001"/>
      </geometry>
      <material name="black_plastic"/>
    </visual>
  </link>
  <joint name="lidar_bottom_lidar_up" type="fixed">
    <parent link="lidar_bottom"/>
    <child link="lidar_up"/>
  </joint>
  <link name="rplidar_frame">
    <visual>
      <geometry>
        <sphere radius="0.001"/>
      </geometry>
      <material name="blue"/>
    </visual>
  </link>
  <joint name="base_link_rplidar_frame" type="fixed">
    <origin rpy="0 0 0" xyz="-0.1246 0 0.28"/>
    <parent link="base_link"/>
    <child link="rplidar_frame"/>
  </joint>

  <link name="x">
    <visual>
      <origin rpy="0 0 0" xyz="1.0 0 0"/>
      <geometry>
        <sphere radius="0.1"/>
      </geometry>
      <material name="blue"/>
    </visual>
  </link>
  <joint name="base_link_x" type="fixed">
    <parent link="base_link"/>
    <child link="x"/>
  </joint>
  <link name="y">
    <visual>
      <origin rpy="0 0 0" xyz="0 1 0"/>
      <geometry>
        <sphere radius="0.1"/>
      </geometry>
      <material name="bronze"/>
    </visual>
  </link>
  <joint name="base_link_y" type="fixed">
    <parent link="base_link"/>
    <child link="y"/>
  </joint>
  <link name="imu">
    <visual>
      <origin rpy="0 0 0" xyz="0.0 0.0 0.24"/>
      <geometry>
        <box size="0.05 0.03 0.004"/>
      </geometry>
      <material name="green"/>
    </visual>
  </link>
  <joint name="base_link_imu" type="fixed">
    <parent link="base_link"/>
    <child link="imu"/>
  </joint>
  <link name="imu_frame">
    <visual>
      <geometry>
        <sphere radius="0.001"/>
      </geometry>
      <material name="blue"/>
    </visual>
  </link>
  <joint name="base_link_imu_frame" type="fixed">
    <origin rpy="0 0 0" xyz="0.0 0 -0.24"/>
    <parent link="base_link"/>
    <child link="imu_frame"/>
  </joint>
</robot>

